<?xml version="1.0" encoding="UTF-8"?>
<!-- Generated by org.testng.reporters.JUnitReportReporter -->
<testsuite hostname="DESKTOP-I7693BL" failures="0" tests="7" name="TestCalc" time="0.014" errors="1" timestamp="2021-08-15T23:13:38 IST" skipped="0">
  <testcase classname="TestCalc" name="test1emptystring" time="0.003"/>
  <system-out/>
  <testcase classname="TestCalc" name="test2returnsinglevalue" time="0.001"/>
  <system-out/>
  <testcase classname="TestCalc" name="test3returnsumoftwoinput" time="0.001"/>
  <system-out/>
  <testcase classname="TestCalc" name="test6throwsexceptionfornegativeinputs" time="0.000">
    <error message="
Method TestCalc.test6throwsexceptionfornegativeinputs()[pri:0, instance:TestCalc@6dbb137d] should have thrown an exception of type class java.lang.Exception" type="org.testng.TestException">
      <![CDATA[org.testng.TestException: 
Method TestCalc.test6throwsexceptionfornegativeinputs()[pri:0, instance:TestCalc@6dbb137d] should have thrown an exception of type class java.lang.Exception
at org.testng.internal.ExpectedExceptionsHolder.noException(ExpectedExceptionsHolder.java:82)
at org.testng.internal.TestInvoker.considerExceptions(TestInvoker.java:749)
at org.testng.internal.TestInvoker.invokeMethod(TestInvoker.java:634)
at org.testng.internal.TestInvoker.invokeTestMethod(TestInvoker.java:173)
at org.testng.internal.MethodRunner.runInSequence(MethodRunner.java:46)
at org.testng.internal.TestInvoker$MethodInvocationAgent.invoke(TestInvoker.java:824)
at org.testng.internal.TestInvoker.invokeTestMethods(TestInvoker.java:146)
at org.testng.internal.TestMethodWorker.invokeTestMethods(TestMethodWorker.java:146)
at org.testng.internal.TestMethodWorker.run(TestMethodWorker.java:128)
at java.base/java.util.ArrayList.forEach(ArrayList.java:1511)
at org.testng.TestRunner.privateRun(TestRunner.java:794)
at org.testng.TestRunner.run(TestRunner.java:596)
at org.testng.SuiteRunner.runTest(SuiteRunner.java:377)
at org.testng.SuiteRunner.runSequentially(SuiteRunner.java:371)
at org.testng.SuiteRunner.privateRun(SuiteRunner.java:332)
at org.testng.SuiteRunner.run(SuiteRunner.java:276)
at org.testng.SuiteRunnerWorker.runSuite(SuiteRunnerWorker.java:53)
at org.testng.SuiteRunnerWorker.run(SuiteRunnerWorker.java:96)
at org.testng.TestNG.runSuitesSequentially(TestNG.java:1212)
at org.testng.TestNG.runSuitesLocally(TestNG.java:1134)
at org.testng.TestNG.runSuites(TestNG.java:1063)
at org.testng.TestNG.run(TestNG.java:1031)
at org.testng.remote.AbstractRemoteTestNG.run(AbstractRemoteTestNG.java:115)
at org.testng.remote.RemoteTestNG.initAndRun(RemoteTestNG.java:251)
at org.testng.remote.RemoteTestNG.main(RemoteTestNG.java:77)
]]>
    </error>
  </testcase> <!-- test6throwsexceptionfornegativeinputs -->
  <system-out/>
  <testcase classname="TestCalc" name="test4returnssumwithnewlinedelimiter" time="0.001"/>
  <system-out/>
  <testcase classname="TestCalc" name="test5threenumsum" time="0.001"/>
  <system-out/>
  <testcase classname="TestCalc" name="init" time="0.007"/>
  <system-out/>
</testsuite> <!-- TestCalc -->
